<?xml version="1.0" encoding="utf-8"?>
<!-- This URDF was automatically created by SolidWorks to URDF Exporter! Originally created by Stephen Brawner (brawner@gmail.com) 
     Commit Version: 1.6.0-1-g15f4949  Build Version: 1.6.7594.29634
     For more information, please see http://wiki.ros.org/sw_urdf_exporter -->
<robot
  name="ROCR6II_URDF_Vertical initialization">
<link name="world" />
  <joint name="world_joint" type="fixed">
    <parent link="world" />
    <child link = "base_link" />
    <origin xyz="0.0 0.0 0.0" rpy="3.1415926536 3.1415926536  0.0" />
  </joint>
  <link name="base"/>
  <joint name="base_link-base_fixed_joint" type="fixed">
      <!-- NOTE: this rotation is only needed as long as base_link itself is
                 not corrected wrt the real robot (ie: rotated over 180
                 degrees)
      -->
      <origin xyz="0 0 0" rpy="0 0 -3.1415926536"/>
      <parent link="base_link"/>
      <child link="base"/>
    </joint>
  <link
    name="base_link">
    <inertial>
      <origin
        xyz="6.0184E-05 -0.0017311 0.027527"
        rpy="0 0 0" />
      <mass
        value="0.13958" />
      <inertia
        ixx="0.00015991"
        ixy="-3.4808E-07"
        ixz="1.9728E-07"
        iyy="0.00016434"
        iyz="5.3805E-07"
        izz="0.0002501" />
    </inertial>
    <visual>
      <origin
        xyz="0 0 0"
        rpy="0 0 0" />
      <geometry>
        <mesh
          filename="package://ROCR6II_URDF_Vertical initialization/meshes/base_link.STL" />
      </geometry>
      <material
        name="">
        <color
          rgba="1 1 1 1" />
      </material>
    </visual>
    <collision>
      <origin
        xyz="0 0 0"
        rpy="0 0 0" />
      <geometry>
        <mesh
          filename="package://ROCR6II_URDF_Vertical initialization/meshes/base_link.STL" />
      </geometry>
    </collision>
  </link>
  <link
    name="shoulder_Link">
    <inertial>
      <origin
        xyz="4.3598E-08 0.0037213 0.0030784"
        rpy="0 0 0" />
      <mass
        value="0.85978" />
      <inertia
        ixx="0.0016777"
        ixy="-6.0007E-09"
        ixz="-2.8617E-09"
        iyy="0.0016433"
        iyz="2.3262E-05"
        izz="0.0010333" />
    </inertial>
    <visual>
      <origin
        xyz="0 0 0"
        rpy="0 0 0" />
      <geometry>
        <mesh
          filename="package://ROCR6II_URDF_Vertical initialization/meshes/shoulder_Link.STL" />
      </geometry>
      <material
        name="">
        <color
          rgba="1 0.27059 0 1" />
      </material>
    </visual>
    <collision>
      <origin
        xyz="0 0 0"
        rpy="0 0 0" />
      <geometry>
        <mesh
          filename="package://ROCR6II_URDF_Vertical initialization/meshes/shoulder_Link.STL" />
      </geometry>
    </collision>
  </link>
  <joint
    name="shoulder_pan_joint"
    type="revolute">
    <origin
      xyz="0 0 0.1215"
      rpy="0 0 0" />
    <parent
      link="base_link" />
    <child
      link="shoulder_Link" />
    <axis
      xyz="0 0 1" />
    <limit
      lower="-3.1416"
      upper="3.1416"
      effort="150"
      velocity="30" />
  </joint>
  <link
    name="upper_arm_Link">
    <inertial>
      <origin
        xyz="-3.3972E-07 0.0032878 0.12622"
        rpy="0 0 0" />
      <mass
        value="1.638" />
      <inertia
        ixx="0.0031418"
        ixy="-7.428E-09"
        ixz="-8.1931E-09"
        iyy="0.0024219"
        iyz="8.4156E-05"
        izz="0.0023531" />
    </inertial>
    <visual>
      <origin
        xyz="0 0 0"
        rpy="0 0 0" />
      <geometry>
        <mesh
          filename="package://ROCR6II_URDF_Vertical initialization/meshes/upper_arm_Link.STL" />
      </geometry>
      <material
        name="">
        <color
          rgba="0.48235 0.40784 0.93333 1" />
      </material>
    </visual>
    <collision>
      <origin
        xyz="0 0 0"
        rpy="0 0 0" />
      <geometry>
        <mesh
          filename="package://ROCR6II_URDF_Vertical initialization/meshes/upper_arm_Link.STL" />
      </geometry>
    </collision>
  </link>
  <joint
    name="shoulder_lift_joint"
    type="revolute">
    <origin
      xyz="0 0.1225 0"
      rpy="0 0 0" />
    <parent
      link="shoulder_Link" />
    <child
      link="upper_arm_Link" />
    <axis
      xyz="0 1 0" />
    <limit
      lower="-3.1416"
      upper="3.1416"
      effort="150"
      velocity="30" />
  </joint>
  <link
    name="forearm_Link">
    <inertial>
      <origin
        xyz="1.5572E-06 -0.0051519 0.20823"
        rpy="0 0 0" />
      <mass
        value="0.60459" />
      <inertia
        ixx="0.0011958"
        ixy="3.3305E-09"
        ixz="-3.0271E-09"
        iyy="0.00092459"
        iyz="2.7412E-05"
        izz="0.00067247" />
    </inertial>
    <visual>
      <origin
        xyz="0 0 0"
        rpy="0 0 0" />
      <geometry>
        <mesh
          filename="package://ROCR6II_URDF_Vertical initialization/meshes/forearm_Link.STL" />
      </geometry>
      <material
        name="">
        <color
          rgba="0.52941 0.80784 0.98039 1" />
      </material>
    </visual>
    <collision>
      <origin
        xyz="0 0 0"
        rpy="0 0 0" />
      <geometry>
        <mesh
          filename="package://ROCR6II_URDF_Vertical initialization/meshes/forearm_Link.STL" />
      </geometry>
    </collision>
  </link>
  <joint
    name="elbow_joint"
    type="revolute">
    <origin
      xyz="0 -0.102 0.3"
      rpy="0 0 0" />
    <parent
      link="upper_arm_Link" />
    <child
      link="forearm_Link" />
    <axis
      xyz="0 1 0" />
    <limit
      lower="-3.1416"
      upper="3.1416"
      effort="150"
      velocity="30" />
  </joint>
  <link
    name="wrist_1_Link">
    <inertial>
      <origin
        xyz="4.1946E-07 0.087294 -0.010645"
        rpy="0 0 0" />
      <mass
        value="0.39508" />
      <inertia
        ixx="0.00051251"
        ixy="8.0364E-10"
        ixz="9.9527E-10"
        iyy="0.00050131"
        iyz="1.198E-05"
        izz="0.00023941" />
    </inertial>
    <visual>
      <origin
        xyz="0 0 0"
        rpy="0 0 0" />
      <geometry>
        <mesh
          filename="package://ROCR6II_URDF_Vertical initialization/meshes/wrist_1_Link.STL" />
      </geometry>
      <material
        name="">
        <color
          rgba="1 0.62745 0.47843 1" />
      </material>
    </visual>
    <collision>
      <origin
        xyz="0 0 0"
        rpy="0 0 0" />
      <geometry>
        <mesh
          filename="package://ROCR6II_URDF_Vertical initialization/meshes/wrist_1_Link.STL" />
      </geometry>
    </collision>
  </link>
  <joint
    name="wrist_1_joint"
    type="revolute">
    <origin
      xyz="0 0 0.276"
      rpy="0 0 0" />
    <parent
      link="forearm_Link" />
    <child
      link="wrist_1_Link" />
    <axis
      xyz="0 1 0" />
    <limit
      lower="-3.1416"
      upper="3.1416"
      effort="150"
      velocity="30" />
  </joint>
  <link
    name="wrist_2_Link">
    <inertial>
      <origin
        xyz="4.4522E-10 -0.010645 0.087294"
        rpy="0 0 0" />
      <mass
        value="0.39508" />
      <inertia
        ixx="0.00051251"
        ixy="2.9744E-10"
        ixz="-1.2E-09"
        iyy="0.00023941"
        iyz="1.198E-05"
        izz="0.0005013" />
    </inertial>
    <visual>
      <origin
        xyz="0 0 0"
        rpy="0 0 0" />
      <geometry>
        <mesh
          filename="package://ROCR6II_URDF_Vertical initialization/meshes/wrist_2_Link.STL" />
      </geometry>
      <material
        name="">
        <color
          rgba="0.59608 0.98431 0.59608 1" />
      </material>
    </visual>
    <collision>
      <origin
        xyz="0 0 0"
        rpy="0 0 0" />
      <geometry>
        <mesh
          filename="package://ROCR6II_URDF_Vertical initialization/meshes/wrist_2_Link.STL" />
      </geometry>
    </collision>
  </link>
  <joint
    name="wrist_2_joint"
    type="revolute">
    <origin
      xyz="0 0.09 0"
      rpy="0 0 0" />
    <parent
      link="wrist_1_Link" />
    <child
      link="wrist_2_Link" />
    <axis
      xyz="0 0 1" />
    <limit
      lower="-3.1416"
      upper="3.1416"
      effort="150"
      velocity="30" />
  </joint>
  <link
    name="wrist_3_Link">
    <inertial>
      <origin
        xyz="-3.3896E-09 0.064961 2.5465E-05"
        rpy="0 0 0" />
      <mass
        value="0.075244" />
      <inertia
        ixx="3.1502E-05"
        ixy="2.9042E-13"
        ixz="6.2304E-12"
        iyy="5.0964E-05"
        iyz="6.2644E-07"
        izz="3.1666E-05" />
    </inertial>
    <visual>
      <origin
        xyz="0 0 0"
        rpy="0 0 0" />
      <geometry>
        <mesh
          filename="package://ROCR6II_URDF_Vertical initialization/meshes/wrist_3_Link.STL" />
      </geometry>
      <material
        name="">
        <color
          rgba="1 1 0 1" />
      </material>
    </visual>
    <collision>
      <origin
        xyz="0 0 0"
        rpy="0 0 0" />
      <geometry>
        <mesh
          filename="package://ROCR6II_URDF_Vertical initialization/meshes/wrist_3_Link.STL" />
      </geometry>
    </collision>
  </link>
  <joint
    name="wrist_3_joint"
    type="revolute">
    <origin
      xyz="0 0 0.09"
      rpy="0 0 0" />
    <parent
      link="wrist_2_Link" />
    <child
      link="wrist_3_Link" />
    <axis
      xyz="0 1 0" />
    <limit
      lower="-3.1416"
      upper="3.1416"
      effort="150"
      velocity="30" />
  </joint>

                      <!--new add content -->
  <joint name="ee_fixed_joint" type="fixed">
    <parent link="wrist_3_Link"/>
    <child link="ee_Link"/>
    <origin rpy="0.0 0.0 1.57079632679" xyz="0.0 0.090 0.0"/>
  </joint>
  <link name="ee_Link">
    <collision>
      <geometry>
        <box size="0.01 0.01 0.01"/>
      </geometry>
      <origin rpy="0 0 0" xyz="-0.01 0 0"/>
    </collision>
  </link>
	
     <!-- Frame coincident with all-zeros TCP on ROCR6II controller -->
  <link name="tool0"/>
  <joint name="wrist_3_Link-tool0_fixed_joint" type="fixed">
    <origin rpy="-1.57079632679 0 0" xyz="0 0.082 0"/>
    <parent link="wrist_3_Link"/>
    <child link="tool0"/>
  </joint>
</robot>